# Advanced C++ Exception Handling - Complete Guide

## 11.4 More About Exception Handling

This section covers advanced features and nuances of C++ exception handling that make it more flexible and convenient to use in complex applications.

---

## Advanced Features Overview

### 1. Catch-All Exception Handler
Sometimes you need an exception handler that catches **all exceptions** regardless of type:

```cpp
catch (...) {
    // process all exceptions
}
```

- The **ellipsis (`...`)** matches any type of data
- Useful for default exception handling
- Prevents unhandled exceptions from causing program termination

### 2. Exception Specifications (Function Throw Lists)
You can **restrict the types of exceptions** that a function can throw back to its caller:

```cpp
ret_type func_name(arg_list) throw(type_list) {
    // function body
}
```

- **`type_list`**: Comma-separated list of allowed exception types
- **Empty list** `throw()`: Function cannot throw any exceptions
- **Violation consequences**: Abnormal program termination via `unexpected()`

### 3. Rethrowing Exceptions
You can **rethrow an exception** from within an exception handler:

```cpp
catch (SomeType& e) {
    // handle partially
    throw;  // rethrow the same exception
}
```

- Use bare `throw;` statement (no exception specified)
- Passes current exception to outer try/catch sequence
- Useful for multi-level exception handling

---

## Detailed Examples

### Example 1: Catch-All Handler

**Purpose:** Demonstrates how `catch(...)` catches all exception types

```cpp
// This example catches all exceptions
#include <iostream>
using namespace std;

void Xhandler(int test) {
    try {
        if(test == 0)
            throw test;      // throw int
        if(test == 1) 
            throw 'a';       // throw char
        if(test == 2)
            throw 123.23;    // throw double
    }
    catch (...) {  // catch all exceptions
        cout << "Caught One!\n";
    }
}

int main() {
    cout << "start\n";
    Xhandler(0);  // throws int
    Xhandler(1);  // throws char  
    Xhandler(2);  // throws double
    cout << "end";
    return 0;
}
```

**Output:**
```
start
Caught One!
Caught One!
Caught One!
end
```

**Detailed Explanation:**
- **Three different exception types** are thrown: `int`, `char`, and `double`
- **Single catch handler**: `catch(...)` catches all three different types
- **Universal matching**: The ellipsis (`...`) acts as a wildcard for any data type
- **Consistent handling**: All exceptions receive the same treatment
- **Key benefit**: Simplifies code when you want uniform handling for all exception types

### Example 2: Catch-All as Default Handler

**Purpose:** Shows using `catch(...)` as a default after specific handlers

```cpp
// This example uses catch(...) as a default
#include <iostream>
using namespace std;

void Xhandler(int test) {
    try {
        if(test == 0)
            throw test;      // throw int
        if(test == 1)
            throw 'a';       // throw char
        if(test == 2)
            throw 123.23;    // throw double
    }
    catch (int i) {  // catch int exceptions specifically
        cout << "Caught " << i << '\n';
    }
    catch (...) {    // catch all other exceptions
        cout << "Caught One!\n";
    }
}

int main() {
    cout << "start\n";
    Xhandler(0);  // throws int - caught by specific handler
    Xhandler(1);  // throws char - caught by default handler
    Xhandler(2);  // throws double - caught by default handler  
    cout << "end";
    return 0;
}
```

**Output:**
```
start
Caught 0
Caught One!
Caught One!
end
```

**Detailed Explanation:**
- **Specific handler first**: `catch(int i)` handles integer exceptions specifically
- **Default handler second**: `catch(...)` handles all other exception types
- **Call 1** `Xhandler(0)`: throws `int 0`, caught by specific `int` handler
- **Call 2** `Xhandler(1)`: throws `char 'a'`, caught by default `...` handler  
- **Call 3** `Xhandler(2)`: throws `double 123.23`, caught by default `...` handler
- **Best practice**: Use `catch(...)` as the **last catch** in a series
- **Safety benefit**: Prevents unhandled exceptions from causing abnormal termination
- **Design pattern**: Handle known exceptions specifically, unknown ones generically

### Example 3: Function Exception Specifications

**Purpose:** Demonstrates restricting exception types a function can throw

```cpp
// Restricting function throw types
#include <iostream>
using namespace std;

// This function can only throw ints, chars, and doubles
void Xhandler(int test) throw(int, char, double) {
    if(test == 0)
        throw test;      // throw int - ALLOWED
    if(test == 1)
        throw 'a';       // throw char - ALLOWED  
    if(test == 2)
        throw 123.23;    // throw double - ALLOWED
}

int main() {
    cout << "start\n";
    
    try {
        Xhandler(0);  // try passing 1 and 2 to Xhandler as well
    }
    catch (int i) {
        cout << "Caught int\n";
    }
    catch (char c) {
        cout << "Caught char\n";
    }
    catch (double d) {
        cout << "Caught double\n";
    }
    
    cout << "end";
    return 0;
}
```

**Output (when called with Xhandler(0)):**
```
start
Caught int
end
```

**Detailed Explanation:**
- **Exception specification**: `throw(int, char, double)` restricts allowed exception types
- **Allowed types**: Function can only throw `int`, `char`, or `double`
- **Enforcement**: If function attempts to throw any other type → `unexpected()` called → abnormal termination
- **Scope of restriction**: Applies only to exceptions **thrown out of the function**
- **Internal exceptions**: Try/catch blocks **within** the function can handle any type
- **Testing restriction**: Remove `int` from the throw list and retry with `Xhandler(0)` to see termination

**Important Notes:**
- Exception specifications apply to **outgoing exceptions** only
- Functions can still catch and handle any exception type internally  
- Violation results in **runtime termination**, not compile-time error

### Example 4: Prohibiting All Exceptions

**Purpose:** Shows how to prevent a function from throwing any exceptions

```cpp
// This function can throw NO exceptions!
void Xhandler(int test) throw() {  // Empty throw specification
    /*
    The following statements no longer work. Instead,
    they will cause an abnormal program termination.
    */
    if(test == 0)
        throw test;     // VIOLATION - will cause unexpected()
    if(test == 1)
        throw 'a';      // VIOLATION - will cause unexpected()
    if(test == 2)
        throw 123.23;   // VIOLATION - will cause unexpected()
}
```

**Detailed Explanation:**
- **Empty throw specification**: `throw()` means **no exceptions allowed**
- **Absolute restriction**: Function cannot throw **any** exception type
- **Violation consequence**: Any throw statement causes `unexpected()` → `terminate()` → abnormal termination
- **Use case**: Critical functions that must never fail with exceptions
- **Design consideration**: Such functions must handle all errors internally

### Example 5: Rethrowing Exceptions

**Purpose:** Demonstrates exception rethrowing for multi-level handling

```cpp
// Example of rethrowing an exception
#include <iostream>
using namespace std;

void Xhandler() {
    try {
        throw "hello";  // throw a const char*
    }
    catch (const char*) {  // catch const char*
        cout << "Caught const char* inside Xhandler\n";
        throw;  // rethrow const char* out of function
    }
}

int main() {
    cout << "start\n";
    
    try {
        Xhandler();
    }
    catch (const char*) {
        cout << "Caught const char* inside main\n";
    }
    
    cout << "end";
    return 0;
}
```

**Output:**
```
start
Caught const char* inside Xhandler
Caught const char* inside main
end
```

**Detailed Explanation:**
- **Initial throw**: `throw "hello"` creates a `const char*` exception
- **First catch**: Exception caught in `Xhandler()` function
- **Partial handling**: Function prints a message but doesn't fully resolve the exception
- **Rethrowing**: `throw;` (no parameters) rethrows the **same exception**
- **Propagation**: Exception travels up to the calling function (`main`)
- **Second catch**: Exception caught again in `main()` function
- **Complete handling**: Both handlers get to process the same exception

**Key Concepts:**
- **Bare throw**: `throw;` rethrows current exception (no new exception created)
- **Exception identity**: Same exception object propagates through multiple handlers
- **Multi-level processing**: Different handlers can handle different aspects
- **Propagation direction**: Always moves toward outer scopes
- **Restriction**: Can only rethrow from within a catch block or functions called from it

---

## Advanced Exception Handling Patterns

### 1. Layered Exception Handling
```cpp
try {
    try {
        // risky operation
        throw SomeException();
    }
    catch (SomeException& e) {
        // handle locally
        // conditionally rethrow
        if (cannotHandleCompletely) {
            throw;  // propagate to outer handler
        }
    }
}
catch (SomeException& e) {
    // final handling
}
```

### 2. Exception Specification Best Practices
```cpp
// Good: Specific about what can be thrown
void parseFile(const string& filename) throw(FileError, ParseError);

// Good: Guarantees no exceptions
void cleanup() throw();

// Deprecated in C++11: Don't specify throw lists
// Use noexcept instead in modern C++
```

### 3. Catch-All Safety Pattern
```cpp
try {
    // potentially throwing operations
}
catch (const KnownException& e) {
    // handle known exceptions
}
catch (const std::exception& e) {
    // handle standard library exceptions  
}
catch (...) {
    // handle any other exceptions
    // log error, cleanup, etc.
    // possibly rethrow
}
```

---

## Exercises

### Exercise 1: Hands-On Practice
**Task:** Before continuing, compile and run all of the examples in this section. Be sure you understand why each program produces the output that it does.

**Learning Objectives:**
- Understand catch-all behavior
- See function exception specifications in action
- Experience exception rethrowing
- Build intuition for advanced exception patterns

**Suggested Experiments:**
1. **Modify Example 2**: Change the order of catch statements and observe behavior
2. **Test Example 3**: Try removing different types from the throw specification
3. **Extend Example 5**: Add more levels of exception rethrowing
4. **Combine patterns**: Use catch-all with rethrowing

### Exercise 2: Code Analysis - Type Mismatch
**Question:** What is wrong with this fragment?

```cpp
try {
    // ...
    throw 10;       // throws int
}
catch (int *p) {    // expects int pointer
    // ...
}
```

**Answer:**
- **Problem**: **Type mismatch** between thrown and caught types
- **Thrown type**: `int` (integer value)
- **Expected type**: `int*` (pointer to integer)
- **Consequence**: Exception will **not be caught** → abnormal program termination
- **Root cause**: `int` and `int*` are completely different types in C++

### Exercise 3: Fixing the Type Mismatch
**Question:** Show one way to fix the preceding fragment.

**Answer:** There are several ways to fix this:

**Solution 1: Match the catch to the throw (Recommended)**
```cpp
try {
    // ...
    throw 10;       // throw int
}
catch (int i) {     // catch int (matching type)
    cout << "Caught integer: " << i << endl;
}
```

**Solution 2: Change throw to match catch**
```cpp
try {
    // ...
    int value = 10;
    throw &value;   // throw int* (pointer to int)
}
catch (int *p) {    // catch int*
    cout << "Caught integer pointer: " << *p << endl;
}
```

**Solution 3: Use catch-all**
```cpp
try {
    // ...
    throw 10;       // throw int
}
catch (...) {       // catch any type
    cout << "Caught some exception" << endl;
}
```

**Best Practice:** **Solution 1** is recommended because it maintains type safety and clarity.

### Exercise 4: Catch-All Expression
**Question:** What catch expression catches all types of exceptions?

**Answer:**
```cpp
catch (...) {
    // handle all exception types
}
```

**Details:**
- **Syntax**: Use three dots (ellipsis) as the parameter
- **Scope**: Matches **any data type** thrown as an exception
- **Positioning**: Should typically be the **last catch** in a series
- **Limitation**: Cannot access the actual exception value
- **Use cases**: 
  - Default/fallback exception handling
  - Preventing unhandled exceptions
  - Cleanup operations that apply to any error

### Exercise 5: Division Function with Exception Handling
**Question:** Here is a skeleton for a function called `divide()`:

```cpp
double divide(double a, double b) {
    // add error handling
    return a/b;
}
```

This function returns the result of dividing a by b. Add error checking to this function using C++ exception handling. Specifically, prevent a divide-by-zero error. Demonstrate your solution in a program.

**Complete Solution:**

```cpp
#include <iostream>
#include <stdexcept>
using namespace std;

// Solution 1: Using string exception
double divide(double a, double b) throw(const char*) {
    if (b == 0.0) {
        throw "Division by zero error!";
    }
    return a / b;
}

// Solution 2: Using custom exception class (more professional)
class DivisionByZeroError {
private:
    string message;
public:
    DivisionByZeroError(const string& msg) : message(msg) {}
    string what() const { return message; }
};

double safeDivide(double a, double b) throw(DivisionByZeroError) {
    if (b == 0.0) {
        throw DivisionByZeroError("Cannot divide by zero!");
    }
    return a / b;
}

// Solution 3: Using standard library exception
double stdDivide(double a, double b) {
    if (b == 0.0) {
        throw runtime_error("Division by zero error!");
    }
    return a / b;
}

// Demonstration program
int main() {
    cout << "=== Division Function Exception Handling Demo ===\n\n";
    
    // Test cases
    double test_cases[][2] = {
        {10.0, 2.0},    // valid division
        {15.0, 3.0},    // valid division
        {7.0, 0.0},     // division by zero
        {-8.0, 4.0}     // valid division
    };
    
    cout << "Testing Solution 1 (string exception):\n";
    for (int i = 0; i < 4; i++) {
        try {
            double result = divide(test_cases[i][0], test_cases[i][1]);
            cout << test_cases[i][0] << " / " << test_cases[i][1] 
                 << " = " << result << endl;
        }
        catch (const char* error) {
            cout << "Error: " << error 
                 << " (" << test_cases[i][0] << " / " << test_cases[i][1] << ")" << endl;
        }
    }
    
    cout << "\nTesting Solution 2 (custom exception class):\n";
    for (int i = 0; i < 4; i++) {
        try {
            double result = safeDivide(test_cases[i][0], test_cases[i][1]);
            cout << test_cases[i][0] << " / " << test_cases[i][1] 
                 << " = " << result << endl;
        }
        catch (const DivisionByZeroError& error) {
            cout << "Error: " << error.what() 
                 << " (" << test_cases[i][0] << " / " << test_cases[i][1] << ")" << endl;
        }
    }
    
    cout << "\nTesting Solution 3 (standard library exception):\n";
    for (int i = 0; i < 4; i++) {
        try {
            double result = stdDivide(test_cases[i][0], test_cases[i][1]);
            cout << test_cases[i][0] << " / " << test_cases[i][1] 
                 << " = " << result << endl;
        }
        catch (const runtime_error& error) {
            cout << "Error: " << error.what() 
                 << " (" << test_cases[i][0] << " / " << test_cases[i][1] << ")" << endl;
        }
    }
    
    return 0;
}
```

**Expected Output:**
```
=== Division Function Exception Handling Demo ===

Testing Solution 1 (string exception):
10 / 2 = 5
15 / 3 = 5
Error: Division by zero error! (7 / 0)
-8 / 4 = -2

Testing Solution 2 (custom exception class):
10 / 2 = 5
15 / 3 = 5
Error: Cannot divide by zero! (7 / 0)
-8 / 4 = -2

Testing Solution 3 (standard library exception):
10 / 2 = 5
15 / 3 = 5
Error: Division by zero error! (7 / 0)
-8 / 4 = -2
```

**Solution Analysis:**

1. **Error Detection**: All solutions check if `b == 0.0` before division
2. **Exception Throwing**: Each uses a different exception type:
   - **Solution 1**: Simple string literal (`const char*`)
   - **Solution 2**: Custom exception class with message storage
   - **Solution 3**: Standard library `runtime_error`
3. **Exception Specifications**: Solutions 1 & 2 use throw specifications
4. **Comprehensive Testing**: Program tests valid divisions and error cases
5. **Proper Handling**: Each solution catches its specific exception type

**Best Practice Recommendations:**
- **Solution 3** (standard library) is generally preferred in modern C++
- **Custom classes** (Solution 2) are good for application-specific errors
- **Always test** both normal and error cases
- **Consider floating-point precision** when comparing with zero

---

## Summary

Advanced C++ exception handling provides powerful tools for robust error management:

1. **`catch(...)`** provides universal exception catching
2. **Exception specifications** control what functions can throw
3. **Rethrowing** enables multi-level exception processing
4. **Proper design** combines specific and general exception handling
5. **Type safety** remains critical in exception handling

These features enable sophisticated error handling strategies suitable for complex applications.