# C++ Exception Handling with new Operator - Complete Guide

## 11.5 Handling Exceptions Thrown by new

This section covers how to handle memory allocation failures when using the `new` operator in C++, building on the exception handling concepts from previous sections.

---

## Historical Context and Standards Compliance

### Evolution of new Operator Behavior

The behavior of the `new` operator has changed several times throughout C++ history:

1. **Original C++**: `new` returned `null` on allocation failure
2. **Later versions**: `new` threw an exception on failure  
3. **Standard C++**: `new` throws exception by default, with optional `null` return available

### Important Compatibility Notes

- **Compiler variations**: Not all compilers currently implement Standard C++ behavior
- **Legacy code**: Older compilers may use different exception names or behaviors
- **Implementation checking**: Always consult your compiler's documentation for specific behavior
- **Migration considerations**: Different approaches needed when upgrading legacy code

---

## Standard C++ new Exception Behavior

### Default Exception Throwing

In **Standard C++**, when an allocation request cannot be honored:

- **Exception thrown**: `bad_alloc` exception is generated
- **Program termination**: If uncaught, the program terminates abnormally
- **Production requirement**: Real applications **must** catch and handle this exception
- **Header requirement**: Must include `<new>` header to access the exception type

### Historical Exception Names

- **Original name**: `xalloc` (used by many older compilers)
- **Standard name**: `bad_alloc` (specified by Standard C++)
- **Future compatibility**: Use `bad_alloc` for new code

### Alternative: nothrow new

Standard C++ also provides a version that returns `null` instead of throwing:

```cpp
p_var = new(nothrow) type;
```

**Use cases:**
- **Legacy code compatibility**: Easier migration from older C++ code
- **malloc() replacement**: Direct substitution for `malloc()` calls
- **Exception-free environments**: When exception handling is not desired

---

## Detailed Examples

### Example 1: Basic Exception Handling for new

**Purpose:** Demonstrates proper exception handling for memory allocation

```cpp
#include <iostream>
#include <new>
using namespace std;

int main() {
    int *p;
    
    try {
        p = new int;  // allocate memory for int
    }
    catch (bad_alloc xa) {
        cout << "Allocation failure.\n";
        return 1;
    }
    
    // Use the allocated memory
    for (*p = 0; *p < 10; (*p)++)
        cout << *p << " ";
    
    delete p;  // free the memory
    return 0;
}
```

**Expected Output (normal execution):**
```
0 1 2 3 4 5 6 7 8 9
```

**Detailed Explanation:**

1. **Header inclusion**: `#include <new>` provides access to `bad_alloc` exception type
2. **Try block**: Contains the potentially failing `new int` operation
3. **Exception handling**: `catch(bad_alloc xa)` catches allocation failures
4. **Error response**: If allocation fails, prints error message and exits with error code
5. **Normal execution**: If allocation succeeds, uses the memory normally
6. **Memory cleanup**: `delete p` releases the allocated memory
7. **Practical note**: This simple allocation is unlikely to fail under normal circumstances

**Key Points:**
- **Exception parameter**: `bad_alloc xa` captures the exception object
- **Error code**: `return 1` indicates program failure to the operating system
- **Resource management**: Always `delete` successfully allocated memory

### Example 2: Forcing Allocation Failure

**Purpose:** Demonstrates `new`'s exception-throwing capability by exhausting system memory

```cpp
// Force an allocation failure
#include <iostream>
#include <new>
using namespace std;

int main() {
    double *p;
    
    // This will eventually run out of memory
    do {
        try {
            p = new double[100000];  // Allocate large array
        }
        catch (bad_alloc xa) {
            cout << "Allocation failure.\n";
            return 1;
        }
    } while (p);
    
    return 0;
}
```

**Expected Output (when memory is exhausted):**
```
Allocation failure.
```

**Detailed Explanation:**

1. **Large allocation**: `new double[100000]` allocates ~800KB per iteration (assuming 8-byte doubles)
2. **Continuous allocation**: `do-while` loop continues allocating until failure
3. **Memory exhaustion**: Eventually, system runs out of available memory
4. **Exception trigger**: When allocation fails, `bad_alloc` exception is thrown
5. **Graceful handling**: Exception is caught and handled appropriately
6. **Memory leak note**: Previously allocated memory is not freed (intentionally for demonstration)

**Important Considerations:**
- **System impact**: This program will consume significant system memory
- **Platform differences**: Memory exhaustion point varies by system
- **Production warning**: Never use this pattern in production code
- **Testing purpose**: Useful for testing exception handling mechanisms

### Example 3: Using new(nothrow) Alternative

**Purpose:** Shows how to use the null-returning version of new

```cpp
// Demonstrate the new(nothrow) alternative
#include <iostream>
#include <new>
using namespace std;

int main() {
    double *p;
    
    // This will eventually run out of memory
    do {
        p = new(nothrow) double[100000];
        
        if (p)
            cout << "Allocation OK\n";
        else
            cout << "Allocation Error.\n";
            
    } while (p);
    
    return 0;
}
```

**Expected Output:**
```
Allocation OK
Allocation OK
Allocation OK
...
Allocation Error.
```

**Detailed Explanation:**

1. **nothrow syntax**: `new(nothrow) double[100000]` uses the non-exception version
2. **Return behavior**: Returns `null` pointer on failure instead of throwing exception
3. **Manual checking**: Must explicitly check if `p` is non-null after each allocation
4. **Success indication**: Non-null pointer indicates successful allocation
5. **Failure indication**: Null pointer indicates allocation failure
6. **Loop termination**: Loop exits when `p` becomes null (allocation fails)

**Comparison with Exception Version:**
- **No try/catch needed**: Simpler syntax, no exception handling required
- **Manual error checking**: Must remember to check pointer after each allocation
- **Legacy compatibility**: Works like original C++ `new` operator
- **Performance**: Slightly faster (no exception overhead)

**When to Use:**
- **Legacy code migration**: When converting old C++ code
- **malloc() replacement**: Direct substitution for `malloc()` calls
- **Exception-free design**: In systems where exceptions are not used
- **Performance-critical code**: Where exception overhead is a concern

---

## Practical Considerations

### Memory Allocation Best Practices

1. **Always handle allocation failures** in production code
2. **Choose appropriate method**: Exception-based vs. null-checking
3. **Resource management**: Use RAII (Resource Acquisition Is Initialization)
4. **Smart pointers**: Consider using `std::unique_ptr` or `std::shared_ptr`

### Exception vs. nothrow Comparison

| Aspect | Exception (`new`) | nothrow (`new(nothrow)`) |
|--------|------------------|-------------------------|
| **Error handling** | Automatic via try/catch | Manual pointer checking |
| **Code complexity** | Cleaner allocation code | Must check each allocation |
| **Legacy compatibility** | Requires exception handling | Direct drop-in replacement |
| **Performance** | Exception overhead | No exception overhead |
| **Error detection** | Guaranteed (exception forces handling) | Easy to forget checks |

---

## Exercises

### Exercise 1: Behavior Comparison
**Question:** Explain the difference between the behavior of `new` and `new(nothrow)` when an allocation failure occurs.

**Answer:**

#### Standard `new` Behavior:
- **On failure**: Throws `bad_alloc` exception
- **Program flow**: Exception propagates up the call stack
- **Handling requirement**: Must be caught with try/catch or program terminates
- **Automatic detection**: Impossible to ignore allocation failure
- **Code pattern**:
```cpp
try {
    ptr = new Type;
    // Continue only if allocation succeeded
} catch (bad_alloc& e) {
    // Handle failure
}
```

#### `new(nothrow)` Behavior:
- **On failure**: Returns null pointer (`nullptr`)
- **Program flow**: Continues normal execution
- **Handling requirement**: Must manually check return value
- **Manual detection**: Easy to forget to check for null
- **Code pattern**:
```cpp
ptr = new(nothrow) Type;
if (!ptr) {
    // Handle failure
} else {
    // Continue with valid pointer
}
```

#### Key Differences:
1. **Error notification**: Exception vs. return value
2. **Handling enforcement**: Automatic vs. manual
3. **Code complexity**: Try/catch vs. if statements
4. **Legacy compatibility**: Modern vs. traditional approach

### Exercise 2: Converting malloc() to Modern C++
**Question:** Given the following fragment, show two ways to convert it into modern C++-style code:

```cpp
p = malloc(sizeof(int));
if (!p) {
    cout << "Allocation error.\n";
    exit(1);
}
```

**Answer:**

#### Method 1: Using Exception-Based new (Recommended)

```cpp
#include <iostream>
#include <new>
using namespace std;

// Modern C++ approach with exceptions
try {
    p = new int;  // Allocate memory for int
    // Continue with normal execution
}
catch (bad_alloc& e) {
    cout << "Allocation error.\n";
    exit(1);
}
```

**Advantages:**
- **Automatic error detection**: Cannot forget to handle allocation failure
- **Type safety**: No manual size calculation required
- **Modern C++ style**: Uses exception handling paradigm
- **Cleaner code**: Separates normal flow from error handling

#### Method 2: Using nothrow new (Legacy Compatible)

```cpp
#include <iostream>
#include <new>
using namespace std;

// Legacy-compatible approach
p = new(nothrow) int;  // Allocate memory for int
if (!p) {
    cout << "Allocation error.\n";
    exit(1);
}
```

**Advantages:**
- **Direct replacement**: Minimal code changes from malloc version
- **No exception handling**: Simple conditional checking
- **Performance**: No exception overhead
- **Familiar pattern**: Similar to traditional C/early C++ style

#### Additional Modern Improvements:

**Method 3: Using Smart Pointers (Best Practice)**
```cpp
#include <iostream>
#include <memory>
using namespace std;

try {
    auto p = make_unique<int>();  // Modern C++ with smart pointer
    // Automatic cleanup, exception-safe
}
catch (bad_alloc& e) {
    cout << "Allocation error.\n";
    exit(1);
}
```

**Method 4: RAII with Stack Allocation**
```cpp
// If possible, avoid dynamic allocation entirely
int value;  // Stack allocation - no failure possible
int* p = &value;  // Use stack-allocated object
```

#### Comparison Summary:

| Approach | Type Safety | Error Handling | Memory Management | Modern C++ |
|----------|-------------|----------------|-------------------|------------|
| **malloc()** | Manual | Manual checking | Manual delete | No |
| **new + exceptions** | Automatic | Automatic | Manual delete | Partial |
| **new(nothrow)** | Automatic | Manual checking | Manual delete | Partial |
| **Smart pointers** | Automatic | Automatic | Automatic | Yes |

**Recommendation:** Use **Method 1** (exception-based) for new code, **Method 2** for legacy code migration, and **Method 3** (smart pointers) for the most modern and safe approach.

---

## Skills Check Exercises

### Mastery Skills Check

#### 1. Generic Mode Function
**Task:** Create a generic function that returns the mode of an array of values. (The mode of a set is the value that occurs most often.)

```cpp
#include <iostream>
#include <map>
#include <vector>
using namespace std;

template <typename T>
T findMode(const T* array, int size) {
    if (size <= 0) {
        throw invalid_argument("Array size must be positive");
    }
    
    map<T, int> frequency;
    
    // Count frequency of each element
    for (int i = 0; i < size; i++) {
        frequency[array[i]]++;
    }
    
    // Find element with maximum frequency
    T mode = array[0];
    int maxCount = 0;
    
    for (const auto& pair : frequency) {
        if (pair.second > maxCount) {
            maxCount = pair.second;
            mode = pair.first;
        }
    }
    
    return mode;
}

// Demonstration
int main() {
    try {
        int intArray[] = {1, 2, 2, 3, 2, 4, 2, 5};
        cout << "Mode of integer array: " << findMode(intArray, 8) << endl;
        
        char charArray[] = {'a', 'b', 'a', 'c', 'a', 'b', 'a'};
        cout << "Mode of character array: " << findMode(charArray, 7) << endl;
        
        double doubleArray[] = {1.1, 2.2, 1.1, 3.3, 1.1};
        cout << "Mode of double array: " << findMode(doubleArray, 5) << endl;
    }
    catch (const exception& e) {
        cout << "Error: " << e.what() << endl;
    }
    
    return 0;
}
```

#### 2. Generic Summation Function
**Task:** Create a generic function that returns the summation of an array of values.

```cpp
#include <iostream>
using namespace std;

template <typename T>
T summation(const T* array, int size) {
    if (size <= 0) {
        throw invalid_argument("Array size must be positive");
    }
    
    T sum = T();  // Initialize with default value (0 for numeric types)
    
    for (int i = 0; i < size; i++) {
        sum += array[i];
    }
    
    return sum;
}

// Demonstration
int main() {
    try {
        int intArray[] = {1, 2, 3, 4, 5};
        cout << "Sum of integers: " << summation(intArray, 5) << endl;
        
        double doubleArray[] = {1.5, 2.5, 3.5, 4.5};
        cout << "Sum of doubles: " << summation(doubleArray, 4) << endl;
        
        float floatArray[] = {0.1f, 0.2f, 0.3f};
        cout << "Sum of floats: " << summation(floatArray, 3) << endl;
    }
    catch (const exception& e) {
        cout << "Error: " << e.what() << endl;
    }
    
    return 0;
}
```

#### 3. Generic Bubble Sort
**Task:** Create a generic bubble sort (or use any other sorting algorithm you like).

```cpp
#include <iostream>
using namespace std;

template <typename T>
void bubbleSort(T* array, int size) {
    if (size <= 0) {
        throw invalid_argument("Array size must be positive");
    }
    
    for (int i = 0; i < size - 1; i++) {
        bool swapped = false;
        
        for (int j = 0; j < size - i - 1; j++) {
            if (array[j] > array[j + 1]) {
                // Swap elements
                T temp = array[j];
                array[j] = array[j + 1];
                array[j + 1] = temp;
                swapped = true;
            }
        }
        
        // If no swapping occurred, array is sorted
        if (!swapped) break;
    }
}

template <typename T>
void printArray(const T* array, int size) {
    for (int i = 0; i < size; i++) {
        cout << array[i] << " ";
    }
    cout << endl;
}

// Demonstration
int main() {
    try {
        int intArray[] = {64, 34, 25, 12, 22, 11, 90};
        int intSize = 7;
        cout << "Original integer array: ";
        printArray(intArray, intSize);
        bubbleSort(intArray, intSize);
        cout << "Sorted integer array: ";
        printArray(intArray, intSize);
        
        double doubleArray[] = {3.14, 2.71, 1.41, 1.73};
        int doubleSize = 4;
        cout << "\nOriginal double array: ";
        printArray(doubleArray, doubleSize);
        bubbleSort(doubleArray, doubleSize);
        cout << "Sorted double array: ";
        printArray(doubleArray, doubleSize);
        
        char charArray[] = {'z', 'a', 'm', 'c', 'b'};
        int charSize = 5;
        cout << "\nOriginal character array: ";
        printArray(charArray, charSize);
        bubbleSort(charArray, charSize);
        cout << "Sorted character array: ";
        printArray(charArray, charSize);
    }
    catch (const exception& e) {
        cout << "Error: " << e.what() << endl;
    }
    
    return 0;
}
```

#### 4. Stack Class for Pairs
**Task:** Rework the stack class so that it can store pairs of different-type objects on the stack.

```cpp
#include <iostream>
#include <new>
using namespace std;

template <typename T1, typename T2>
class PairStack {
private:
    struct Pair {
        T1 first;
        T2 second;
        Pair(const T1& f, const T2& s) : first(f), second(s) {}
    };
    
    Pair** stack;
    int size;
    int top;
    
public:
    PairStack(int s) throw(bad_alloc) : size(s), top(-1) {
        try {
            stack = new Pair*[size];
            for (int i = 0; i < size; i++) {
                stack[i] = nullptr;
            }
        }
        catch (bad_alloc& e) {
            throw;
        }
    }
    
    ~PairStack() {
        for (int i = 0; i <= top; i++) {
            delete stack[i];
        }
        delete[] stack;
    }
    
    void push(const T1& first, const T2& second) throw(bad_alloc, overflow_error) {
        if (top >= size - 1) {
            throw overflow_error("Stack overflow");
        }
        
        try {
            stack[++top] = new Pair(first, second);
        }
        catch (bad_alloc& e) {
            --top;  // Restore top if allocation failed
            throw;
        }
    }
    
    pair<T1, T2> pop() throw(underflow_error) {
        if (top < 0) {
            throw underflow_error("Stack underflow");
        }
        
        Pair* pairPtr = stack[top];
        pair<T1, T2> result(pairPtr->first, pairPtr->second);
        delete pairPtr;
        stack[top--] = nullptr;
        
        return result;
    }
    
    bool isEmpty() const {
        return top < 0;
    }
    
    bool isFull() const {
        return top >= size - 1;
    }
    
    int getSize() const {
        return top + 1;
    }
};

// Custom exception classes
class overflow_error : public exception {
private:
    string message;
public:
    overflow_error(const string& msg) : message(msg) {}
    const char* what() const noexcept override {
        return message.c_str();
    }
};

class underflow_error : public exception {
private:
    string message;
public:
    underflow_error(const string& msg) : message(msg) {}
    const char* what() const noexcept override {
        return message.c_str();
    }
};

// Demonstration
int main() {
    try {
        // Stack of int-string pairs
        PairStack<int, string> intStringStack(5);
        
        cout << "Pushing pairs to stack:\n";
        intStringStack.push(1, "One");
        intStringStack.push(2, "Two");
        intStringStack.push(3, "Three");
        
        cout << "Popping pairs from stack:\n";
        while (!intStringStack.isEmpty()) {
            auto p = intStringStack.pop();
            cout << "(" << p.first << ", " << p.second << ")\n";
        }
        
        // Stack of double-char pairs
        PairStack<double, char> doubleCharStack(3);
        
        cout << "\nPushing double-char pairs:\n";
        doubleCharStack.push(3.14, 'A');
        doubleCharStack.push(2.71, 'B');
        
        cout << "Popping double-char pairs:\n";
        while (!doubleCharStack.isEmpty()) {
            auto p = doubleCharStack.pop();
            cout << "(" << p.first << ", " << p.second << ")\n";
        }
        
    }
    catch (const exception& e) {
        cout << "Error: " << e.what() << endl;
    }
    
    return 0;
}
```

#### 5. General Forms of try, catch, and throw
**Task:** Show the general forms of try, catch, and throw. In your own words, describe their operation.

**Answer:**

#### General Forms:

```cpp
// TRY block - monitors code for exceptions
try {
    // statements that might throw exceptions
    // ...
}

// CATCH blocks - handle specific exception types
catch (ExceptionType1 parameter) {
    // handle ExceptionType1
}
catch (ExceptionType2 parameter) {
    // handle ExceptionType2
}
catch (...) {
    // catch-all handler for any remaining types
}

// THROW statement - generates an exception
throw expression;  // throws an exception of expression's type
throw;            // rethrows current exception (only in catch blocks)
```

#### Operation Description:

**TRY Block:**
- **Purpose**: Establishes a monitored region where exceptions can be caught
- **Scope**: Any code within the try block (or functions called from it) can throw exceptions
- **Behavior**: Normal execution continues until an exception is thrown
- **Termination**: When exception occurs, control immediately transfers to appropriate catch block

**CATCH Blocks:**
- **Purpose**: Handle specific types of exceptions thrown from the try block
- **Type matching**: Each catch handles one specific exception type
- **Parameter**: Optional parameter receives the thrown exception value
- **Selection**: First matching catch block executes, others are skipped
- **Ordering**: More specific exception types should come before general ones

**THROW Statement:**
- **Purpose**: Generates an exception to signal an error condition
- **Expression form**: `throw value;` creates new exception of value's type
- **Rethrow form**: `throw;` propagates current exception to outer handler
- **Immediate effect**: Control transfers immediately to matching catch block
- **Stack unwinding**: Local objects are destroyed during exception propagation

#### 6. Exception-Safe Stack Class
**Task:** Rework the stack class so that stack over- and underflows are handled as exceptions.

```cpp
#include <iostream>
#include <new>
using namespace std;

// Custom exception classes
class StackOverflow : public exception {
    const char* what() const noexcept override {
        return "Stack overflow - cannot push to full stack";
    }
};

class StackUnderflow : public exception {
    const char* what() const noexcept override {
        return "Stack underflow - cannot pop from empty stack";
    }
};

template <typename T>
class ExceptionSafeStack {
private:
    T* stack;
    int size;
    int top;
    
public:
    // Constructor with exception handling
    ExceptionSafeStack(int s) throw(bad_alloc) : size(s), top(-1) {
        try {
            stack = new T[size];
        }
        catch (bad_alloc& e) {
            throw;  // Rethrow allocation failure
        }
    }
    
    // Destructor
    ~ExceptionSafeStack() {
        delete[] stack;
    }
    
    // Copy constructor
    ExceptionSafeStack(const ExceptionSafeStack& other) throw(bad_alloc) 
        : size(other.size), top(other.top) {
        try {
            stack = new T[size];
            for (int i = 0; i <= top; i++) {
                stack[i] = other.stack[i];
            }
        }
        catch (bad_alloc& e) {
            throw;
        }
    }
    
    // Assignment operator
    ExceptionSafeStack& operator=(const ExceptionSafeStack& other) throw(bad_alloc) {
        if (this != &other) {
            T* newStack;
            try {
                newStack = new T[other.size];
            }
            catch (bad_alloc& e) {
                throw;
            }
            
            delete[] stack;
            stack = newStack;
            size = other.size;
            top = other.top;
            
            for (int i = 0; i <= top; i++) {
                stack[i] = other.stack[i];
            }
        }
        return *this;
    }
    
    // Push with overflow exception
    void push(const T& item) throw(StackOverflow) {
        if (top >= size - 1) {
            throw StackOverflow();
        }
        stack[++top] = item;
    }
    
    // Pop with underflow exception
    T pop() throw(StackUnderflow) {
        if (top < 0) {
            throw StackUnderflow();
        }
        return stack[top--];
    }
    
    // Peek without modifying stack
    T peek() const throw(StackUnderflow) {
        if (top < 0) {
            throw StackUnderflow();
        }
        return stack[top];
    }
    
    // Utility functions
    bool isEmpty() const { return top < 0; }
    bool isFull() const { return top >= size - 1; }
    int getSize() const { return top + 1; }
    int getCapacity() const { return size; }
};

// Demonstration program
int main() {
    try {
        ExceptionSafeStack<int> intStack(5);
        
        cout << "Testing stack operations:\n";
        
        // Test normal operations
        cout << "Pushing elements: ";
        for (int i = 1; i <= 5; i++) {
            intStack.push(i);
            cout << i << " ";
        }
        cout << "\nStack size: " << intStack.getSize() << endl;
        
        // Test overflow
        cout << "\nTesting overflow:\n";
        try {
            intStack.push(6);  // Should throw StackOverflow
        }
        catch (const StackOverflow& e) {
            cout << "Caught overflow: " << e.what() << endl;
        }
        
        // Test normal popping
        cout << "\nPopping elements: ";
        while (!intStack.isEmpty()) {
            cout << intStack.pop() << " ";
        }
        cout << "\nStack size: " << intStack.getSize() << endl;
        
        // Test underflow
        cout << "\nTesting underflow:\n";
        try {
            intStack.pop();  // Should throw StackUnderflow
        }
        catch (const StackUnderflow& e) {
            cout << "Caught underflow: " << e.what() << endl;
        }
        
        // Test memory allocation failure simulation
        cout << "\nTesting with different types:\n";
        ExceptionSafeStack<string> stringStack(3);
        stringStack.push("Hello");
        stringStack.push("World");
        cout << "String stack peek: " << stringStack.peek() << endl;
        
    }
    catch (const bad_alloc& e) {
        cout << "Memory allocation failed: " << e.what() << endl;
    }
    catch (const exception& e) {
        cout << "Unexpected error: " << e.what() << endl;
    }
    
    return 0;
}
```

#### 7. Custom Termination Functions
**Task:** Check your compiler's documentation. See whether it supports the terminate() and unexpected() functions.

**Answer:**

Most modern C++ compilers support `terminate()` and `unexpected()` functions. Here's how to create custom termination handlers:

```cpp
#include <iostream>
#include <exception>
#include <new>
using namespace std;

// Custom terminate handler
void customTerminate() {
    cout << "Custom terminate handler called!\n";
    cout << "Program is terminating due to unhandled exception.\n";
    
    // Log error information, cleanup resources, etc.
    // Note: Must not throw exceptions or return
    
    abort();  // Required - must terminate the program
}

// Custom unexpected handler (deprecated in C++11)
void customUnexpected() {
    cout << "Custom unexpected handler called!\n";
    cout << "Function threw an exception not in its throw specification.\n";
    
    // Can throw a different exception or terminate
    terminate();  // Usually best to terminate
}

// Function with throw specification (for testing unexpected)
void restrictedFunction() throw(int) {
    throw string("Not allowed!");  // Violates throw specification
}

// Demonstration program
int main() {
    // Set custom handlers
    set_terminate(customTerminate);
    // set_unexpected(customUnexpected);  // Deprecated in C++11
    
    cout << "Testing custom termination handlers:\n\n";
    
    // Test 1: Unhandled exception
    cout << "Test 1: Throwing unhandled exception\n";
    try {
        // Comment out this try-catch to test terminate handler
        throw runtime_error("This will be handled normally");
    }
    catch (const exception& e) {
        cout << "Exception caught: " << e.what() << endl;
    }
    
    // Test 2: Allocation failure with custom handling
    cout << "\nTest 2: Allocation with error handling\n";
    try {
        // Force allocation failure (may not work on all systems)
        while (true) {
            new char[1000000];  // Will eventually fail
        }
    }
    catch (const bad_alloc& e) {
        cout << "Allocation failure handled: " << e.what() << endl;
    }
    
    cout << "\nProgram completed normally.\n";
    
    // Uncomment to test terminate handler:
    // throw runtime_error("Unhandled exception");
    
    return 0;
}
```

**Modern C++11+ Approach:**
```cpp
#include <iostream>
#include <exception>
using namespace std;

void modernTerminateHandler() {
    cout << "Modern terminate handler!\n";
    
    // Get information about current exception
    try {
        auto eptr = current_exception();
        if (eptr) {
            rethrow_exception(eptr);
        }
    }
    catch (const exception& e) {
        cout << "Terminating due to exception: " << e.what() << endl;
    }
    catch (...) {
        cout << "Terminating due to unknown exception" << endl;
    }
    
    abort();